2018-05-29 13:36:52,780 ERROR: Exception on /edit_module/account_analytic_line_list/version_8 [POST] [in d:\flask\stageopdracht\venv\lib\site-packages\flask\app.py:1560]
Traceback (most recent call last):
  File "d:\flask\stageopdracht\venv\lib\site-packages\flask\app.py", line 1982, in wsgi_app
    response = self.full_dispatch_request()
  File "d:\flask\stageopdracht\venv\lib\site-packages\flask\app.py", line 1614, in full_dispatch_request
    rv = self.handle_user_exception(e)
  File "d:\flask\stageopdracht\venv\lib\site-packages\flask\app.py", line 1517, in handle_user_exception
    reraise(exc_type, exc_value, tb)
  File "d:\flask\stageopdracht\venv\lib\site-packages\flask\_compat.py", line 33, in reraise
    raise value
  File "d:\flask\stageopdracht\venv\lib\site-packages\flask\app.py", line 1612, in full_dispatch_request
    rv = self.dispatch_request()
  File "d:\flask\stageopdracht\venv\lib\site-packages\flask\app.py", line 1598, in dispatch_request
    return self.view_functions[rule.endpoint](**req.view_args)
  File "D:\flask\stageopdracht\app\routes.py", line 177, in edit_module
    customer_list = customer_list.remove(name)
ValueError: list.remove(x): x not in list
2018-05-29 13:39:53,755 ERROR: Exception on /edit_module/account_analytic_line_list/version_8 [POST] [in d:\flask\stageopdracht\venv\lib\site-packages\flask\app.py:1560]
Traceback (most recent call last):
  File "d:\flask\stageopdracht\venv\lib\site-packages\flask\app.py", line 1982, in wsgi_app
    response = self.full_dispatch_request()
  File "d:\flask\stageopdracht\venv\lib\site-packages\flask\app.py", line 1614, in full_dispatch_request
    rv = self.handle_user_exception(e)
  File "d:\flask\stageopdracht\venv\lib\site-packages\flask\app.py", line 1517, in handle_user_exception
    reraise(exc_type, exc_value, tb)
  File "d:\flask\stageopdracht\venv\lib\site-packages\flask\_compat.py", line 33, in reraise
    raise value
  File "d:\flask\stageopdracht\venv\lib\site-packages\flask\app.py", line 1612, in full_dispatch_request
    rv = self.dispatch_request()
  File "d:\flask\stageopdracht\venv\lib\site-packages\flask\app.py", line 1598, in dispatch_request
    return self.view_functions[rule.endpoint](**req.view_args)
  File "D:\flask\stageopdracht\app\routes.py", line 187, in edit_module
    customers += name + ' '
TypeError: can only concatenate list (not "str") to list
2018-05-29 13:46:51,725 INFO: App startup [in D:\flask\stageopdracht\app\__init__.py:33]
2018-05-29 13:50:48,553 INFO: App startup [in D:\flask\stageopdracht\app\__init__.py:33]
2018-05-29 13:51:25,937 ERROR: Exception on /edit_module/account_analytic_line_list/version_8 [POST] [in d:\flask\stageopdracht\venv\lib\site-packages\flask\app.py:1560]
Traceback (most recent call last):
  File "d:\flask\stageopdracht\venv\lib\site-packages\flask\app.py", line 1982, in wsgi_app
    response = self.full_dispatch_request()
  File "d:\flask\stageopdracht\venv\lib\site-packages\flask\app.py", line 1614, in full_dispatch_request
    rv = self.handle_user_exception(e)
  File "d:\flask\stageopdracht\venv\lib\site-packages\flask\app.py", line 1517, in handle_user_exception
    reraise(exc_type, exc_value, tb)
  File "d:\flask\stageopdracht\venv\lib\site-packages\flask\_compat.py", line 33, in reraise
    raise value
  File "d:\flask\stageopdracht\venv\lib\site-packages\flask\app.py", line 1612, in full_dispatch_request
    rv = self.dispatch_request()
  File "d:\flask\stageopdracht\venv\lib\site-packages\flask\app.py", line 1598, in dispatch_request
    return self.view_functions[rule.endpoint](**req.view_args)
  File "D:\flask\stageopdracht\app\routes.py", line 186, in edit_module
    customers = ' '.join(customer_list)
TypeError: sequence item 0: expected str instance, list found
2018-05-29 13:52:48,222 INFO: App startup [in D:\flask\stageopdracht\app\__init__.py:33]
2018-05-29 13:53:00,384 ERROR: Exception on /edit_module/account_analytic_line_list/version_8 [POST] [in d:\flask\stageopdracht\venv\lib\site-packages\flask\app.py:1560]
Traceback (most recent call last):
  File "d:\flask\stageopdracht\venv\lib\site-packages\flask\app.py", line 1982, in wsgi_app
    response = self.full_dispatch_request()
  File "d:\flask\stageopdracht\venv\lib\site-packages\flask\app.py", line 1614, in full_dispatch_request
    rv = self.handle_user_exception(e)
  File "d:\flask\stageopdracht\venv\lib\site-packages\flask\app.py", line 1517, in handle_user_exception
    reraise(exc_type, exc_value, tb)
  File "d:\flask\stageopdracht\venv\lib\site-packages\flask\_compat.py", line 33, in reraise
    raise value
  File "d:\flask\stageopdracht\venv\lib\site-packages\flask\app.py", line 1612, in full_dispatch_request
    rv = self.dispatch_request()
  File "d:\flask\stageopdracht\venv\lib\site-packages\flask\app.py", line 1598, in dispatch_request
    return self.view_functions[rule.endpoint](**req.view_args)
  File "D:\flask\stageopdracht\app\routes.py", line 186, in edit_module
    customers = ' '.join(customer_list)
TypeError: sequence item 0: expected str instance, list found
2018-05-29 13:55:06,658 INFO: App startup [in D:\flask\stageopdracht\app\__init__.py:33]
2018-05-29 13:55:14,728 ERROR: Exception on /edit_module/account_analytic_line_list/version_8 [POST] [in d:\flask\stageopdracht\venv\lib\site-packages\flask\app.py:1560]
Traceback (most recent call last):
  File "d:\flask\stageopdracht\venv\lib\site-packages\flask\app.py", line 1982, in wsgi_app
    response = self.full_dispatch_request()
  File "d:\flask\stageopdracht\venv\lib\site-packages\flask\app.py", line 1614, in full_dispatch_request
    rv = self.handle_user_exception(e)
  File "d:\flask\stageopdracht\venv\lib\site-packages\flask\app.py", line 1517, in handle_user_exception
    reraise(exc_type, exc_value, tb)
  File "d:\flask\stageopdracht\venv\lib\site-packages\flask\_compat.py", line 33, in reraise
    raise value
  File "d:\flask\stageopdracht\venv\lib\site-packages\flask\app.py", line 1612, in full_dispatch_request
    rv = self.dispatch_request()
  File "d:\flask\stageopdracht\venv\lib\site-packages\flask\app.py", line 1598, in dispatch_request
    return self.view_functions[rule.endpoint](**req.view_args)
  File "D:\flask\stageopdracht\app\routes.py", line 179, in edit_module
    customer_list.remove(name)
ValueError: list.remove(x): x not in list
2018-05-29 14:33:11,890 INFO: App startup [in D:\flask\stageopdracht\app\__init__.py:33]
2018-05-29 14:43:16,185 INFO: App startup [in D:\flask\stageopdracht\app\__init__.py:33]
2018-05-29 14:43:22,210 ERROR: Exception on /edit_module/account_analytic_line_list/version_8 [GET] [in d:\flask\stageopdracht\venv\lib\site-packages\flask\app.py:1560]
Traceback (most recent call last):
  File "d:\flask\stageopdracht\venv\lib\site-packages\flask\app.py", line 1982, in wsgi_app
    response = self.full_dispatch_request()
  File "d:\flask\stageopdracht\venv\lib\site-packages\flask\app.py", line 1614, in full_dispatch_request
    rv = self.handle_user_exception(e)
  File "d:\flask\stageopdracht\venv\lib\site-packages\flask\app.py", line 1517, in handle_user_exception
    reraise(exc_type, exc_value, tb)
  File "d:\flask\stageopdracht\venv\lib\site-packages\flask\_compat.py", line 33, in reraise
    raise value
  File "d:\flask\stageopdracht\venv\lib\site-packages\flask\app.py", line 1612, in full_dispatch_request
    rv = self.dispatch_request()
  File "d:\flask\stageopdracht\venv\lib\site-packages\flask\app.py", line 1598, in dispatch_request
    return self.view_functions[rule.endpoint](**req.view_args)
  File "D:\flask\stageopdracht\app\routes.py", line 154, in edit_module
    return render_template('edit_module.html', title='Edit Module', form=form)
  File "d:\flask\stageopdracht\venv\lib\site-packages\flask\templating.py", line 134, in render_template
    context, ctx.app)
  File "d:\flask\stageopdracht\venv\lib\site-packages\flask\templating.py", line 116, in _render
    rv = template.render(context)
  File "d:\flask\stageopdracht\venv\lib\site-packages\jinja2\asyncsupport.py", line 76, in render
    return original_render(self, *args, **kwargs)
  File "d:\flask\stageopdracht\venv\lib\site-packages\jinja2\environment.py", line 1008, in render
    return self.environment.handle_exception(exc_info, True)
  File "d:\flask\stageopdracht\venv\lib\site-packages\jinja2\environment.py", line 780, in handle_exception
    reraise(exc_type, exc_value, tb)
  File "d:\flask\stageopdracht\venv\lib\site-packages\jinja2\_compat.py", line 37, in reraise
    raise value.with_traceback(tb)
  File "D:\flask\stageopdracht\app\templates\edit_module.html", line 1, in top-level template code
    {% extends 'base.html' %}
  File "D:\flask\stageopdracht\app\templates\base.html", line 21, in top-level template code
    {% block content %} {% endblock %}
  File "D:\flask\stageopdracht\app\templates\edit_module.html", line 18, in block "content"
    <div>{{ form.customer_delete.label }}</div>
  File "d:\flask\stageopdracht\venv\lib\site-packages\jinja2\environment.py", line 430, in getattr
    return getattr(obj, attribute)
jinja2.exceptions.UndefinedError: 'app.forms.EditModuleForm object' has no attribute 'customer_delete'
2018-05-29 14:46:48,982 INFO: App startup [in D:\flask\stageopdracht\app\__init__.py:33]
