2018-05-17 09:36:57,830 ERROR: Exception on /version_details/account-analytic/8.0 [GET] [in d:\flask\stageopdracht\venv\lib\site-packages\flask\app.py:1560]
Traceback (most recent call last):
  File "d:\flask\stageopdracht\venv\lib\site-packages\flask\app.py", line 1982, in wsgi_app
    response = self.full_dispatch_request()
  File "d:\flask\stageopdracht\venv\lib\site-packages\flask\app.py", line 1614, in full_dispatch_request
    rv = self.handle_user_exception(e)
  File "d:\flask\stageopdracht\venv\lib\site-packages\flask\app.py", line 1517, in handle_user_exception
    reraise(exc_type, exc_value, tb)
  File "d:\flask\stageopdracht\venv\lib\site-packages\flask\_compat.py", line 33, in reraise
    raise value
  File "d:\flask\stageopdracht\venv\lib\site-packages\flask\app.py", line 1612, in full_dispatch_request
    rv = self.dispatch_request()
  File "d:\flask\stageopdracht\venv\lib\site-packages\flask\app.py", line 1598, in dispatch_request
    return self.view_functions[rule.endpoint](**req.view_args)
  File "D:\flask\stageopdracht\app\routes.py", line 57, in version_details
    form=form)
  File "d:\flask\stageopdracht\venv\lib\site-packages\flask\templating.py", line 134, in render_template
    context, ctx.app)
  File "d:\flask\stageopdracht\venv\lib\site-packages\flask\templating.py", line 116, in _render
    rv = template.render(context)
  File "d:\flask\stageopdracht\venv\lib\site-packages\jinja2\asyncsupport.py", line 76, in render
    return original_render(self, *args, **kwargs)
  File "d:\flask\stageopdracht\venv\lib\site-packages\jinja2\environment.py", line 1008, in render
    return self.environment.handle_exception(exc_info, True)
  File "d:\flask\stageopdracht\venv\lib\site-packages\jinja2\environment.py", line 780, in handle_exception
    reraise(exc_type, exc_value, tb)
  File "d:\flask\stageopdracht\venv\lib\site-packages\jinja2\_compat.py", line 37, in reraise
    raise value.with_traceback(tb)
  File "D:\flask\stageopdracht\app\templates\version_details.html", line 1, in top-level template code
    {% extends "base.html" %}
  File "D:\flask\stageopdracht\app\templates\base.html", line 20, in top-level template code
    {% block content %} {% endblock %}
  File "D:\flask\stageopdracht\app\templates\version_details.html", line 3, in block "content"
    <div><p>Selected version: {{ version_x }} <br> Current Repository: {{ modules[0].repo_name }}</p></div>
  File "d:\flask\stageopdracht\venv\lib\site-packages\jinja2\environment.py", line 430, in getattr
    return getattr(obj, attribute)
jinja2.exceptions.UndefinedError: None has no element 0
2018-05-17 09:37:15,299 INFO: App startup [in D:\flask\stageopdracht\app\__init__.py:33]
2018-05-17 09:37:16,403 ERROR: Exception on /version_details/account-analytic/8.0 [GET] [in d:\flask\stageopdracht\venv\lib\site-packages\flask\app.py:1560]
Traceback (most recent call last):
  File "d:\flask\stageopdracht\venv\lib\site-packages\flask\app.py", line 1982, in wsgi_app
    response = self.full_dispatch_request()
  File "d:\flask\stageopdracht\venv\lib\site-packages\flask\app.py", line 1614, in full_dispatch_request
    rv = self.handle_user_exception(e)
  File "d:\flask\stageopdracht\venv\lib\site-packages\flask\app.py", line 1517, in handle_user_exception
    reraise(exc_type, exc_value, tb)
  File "d:\flask\stageopdracht\venv\lib\site-packages\flask\_compat.py", line 33, in reraise
    raise value
  File "d:\flask\stageopdracht\venv\lib\site-packages\flask\app.py", line 1612, in full_dispatch_request
    rv = self.dispatch_request()
  File "d:\flask\stageopdracht\venv\lib\site-packages\flask\app.py", line 1598, in dispatch_request
    return self.view_functions[rule.endpoint](**req.view_args)
  File "D:\flask\stageopdracht\app\routes.py", line 57, in version_details
    form=form)
  File "d:\flask\stageopdracht\venv\lib\site-packages\flask\templating.py", line 134, in render_template
    context, ctx.app)
  File "d:\flask\stageopdracht\venv\lib\site-packages\flask\templating.py", line 116, in _render
    rv = template.render(context)
  File "d:\flask\stageopdracht\venv\lib\site-packages\jinja2\asyncsupport.py", line 76, in render
    return original_render(self, *args, **kwargs)
  File "d:\flask\stageopdracht\venv\lib\site-packages\jinja2\environment.py", line 1008, in render
    return self.environment.handle_exception(exc_info, True)
  File "d:\flask\stageopdracht\venv\lib\site-packages\jinja2\environment.py", line 780, in handle_exception
    reraise(exc_type, exc_value, tb)
  File "d:\flask\stageopdracht\venv\lib\site-packages\jinja2\_compat.py", line 37, in reraise
    raise value.with_traceback(tb)
  File "D:\flask\stageopdracht\app\templates\version_details.html", line 1, in top-level template code
    {% extends "base.html" %}
  File "D:\flask\stageopdracht\app\templates\base.html", line 20, in top-level template code
    {% block content %} {% endblock %}
  File "D:\flask\stageopdracht\app\templates\version_details.html", line 3, in block "content"
    <div><p>Selected version: {{ version_x }} <br> Current Repository: {{ modules[0].repo_name }}</p></div>
  File "d:\flask\stageopdracht\venv\lib\site-packages\jinja2\environment.py", line 430, in getattr
    return getattr(obj, attribute)
jinja2.exceptions.UndefinedError: None has no element 0
2018-05-17 09:53:23,428 INFO: App startup [in D:\flask\stageopdracht\app\__init__.py:33]
2018-05-17 09:53:39,381 ERROR: Exception on /rating_review/account_analytic_line_list/version_8 [POST] [in d:\flask\stageopdracht\venv\lib\site-packages\flask\app.py:1560]
Traceback (most recent call last):
  File "d:\flask\stageopdracht\venv\lib\site-packages\flask\app.py", line 1982, in wsgi_app
    response = self.full_dispatch_request()
  File "d:\flask\stageopdracht\venv\lib\site-packages\flask\app.py", line 1614, in full_dispatch_request
    rv = self.handle_user_exception(e)
  File "d:\flask\stageopdracht\venv\lib\site-packages\flask\app.py", line 1517, in handle_user_exception
    reraise(exc_type, exc_value, tb)
  File "d:\flask\stageopdracht\venv\lib\site-packages\flask\_compat.py", line 33, in reraise
    raise value
  File "d:\flask\stageopdracht\venv\lib\site-packages\flask\app.py", line 1612, in full_dispatch_request
    rv = self.dispatch_request()
  File "d:\flask\stageopdracht\venv\lib\site-packages\flask\app.py", line 1598, in dispatch_request
    return self.view_functions[rule.endpoint](**req.view_args)
  File "D:\flask\stageopdracht\app\routes.py", line 103, in rating_review
    return redirect(url_for('version_datail'),module.repo_name, version_x)
  File "d:\flask\stageopdracht\venv\lib\site-packages\flask\helpers.py", line 333, in url_for
    return appctx.app.handle_url_build_error(error, endpoint, values)
  File "d:\flask\stageopdracht\venv\lib\site-packages\flask\app.py", line 1805, in handle_url_build_error
    reraise(exc_type, exc_value, tb)
  File "d:\flask\stageopdracht\venv\lib\site-packages\flask\_compat.py", line 33, in reraise
    raise value
  File "d:\flask\stageopdracht\venv\lib\site-packages\flask\helpers.py", line 323, in url_for
    force_external=external)
  File "d:\flask\stageopdracht\venv\lib\site-packages\werkzeug\routing.py", line 1776, in build
    raise BuildError(endpoint, values, method, self)
werkzeug.routing.BuildError: Could not build url for endpoint 'version_datail'. Did you mean 'version_details' instead?
2018-05-17 09:53:54,893 INFO: App startup [in D:\flask\stageopdracht\app\__init__.py:33]
2018-05-17 09:54:26,517 ERROR: Exception on /rating_review/account_analytic_line_list/version_8 [POST] [in d:\flask\stageopdracht\venv\lib\site-packages\flask\app.py:1560]
Traceback (most recent call last):
  File "d:\flask\stageopdracht\venv\lib\site-packages\flask\app.py", line 1982, in wsgi_app
    response = self.full_dispatch_request()
  File "d:\flask\stageopdracht\venv\lib\site-packages\flask\app.py", line 1614, in full_dispatch_request
    rv = self.handle_user_exception(e)
  File "d:\flask\stageopdracht\venv\lib\site-packages\flask\app.py", line 1517, in handle_user_exception
    reraise(exc_type, exc_value, tb)
  File "d:\flask\stageopdracht\venv\lib\site-packages\flask\_compat.py", line 33, in reraise
    raise value
  File "d:\flask\stageopdracht\venv\lib\site-packages\flask\app.py", line 1612, in full_dispatch_request
    rv = self.dispatch_request()
  File "d:\flask\stageopdracht\venv\lib\site-packages\flask\app.py", line 1598, in dispatch_request
    return self.view_functions[rule.endpoint](**req.view_args)
  File "D:\flask\stageopdracht\app\routes.py", line 103, in rating_review
    return redirect(url_for('version_datails'),module.repo_name, version_x)
  File "d:\flask\stageopdracht\venv\lib\site-packages\flask\helpers.py", line 333, in url_for
    return appctx.app.handle_url_build_error(error, endpoint, values)
  File "d:\flask\stageopdracht\venv\lib\site-packages\flask\app.py", line 1805, in handle_url_build_error
    reraise(exc_type, exc_value, tb)
  File "d:\flask\stageopdracht\venv\lib\site-packages\flask\_compat.py", line 33, in reraise
    raise value
  File "d:\flask\stageopdracht\venv\lib\site-packages\flask\helpers.py", line 323, in url_for
    force_external=external)
  File "d:\flask\stageopdracht\venv\lib\site-packages\werkzeug\routing.py", line 1776, in build
    raise BuildError(endpoint, values, method, self)
werkzeug.routing.BuildError: Could not build url for endpoint 'version_datails'. Did you mean 'version_details' instead?
2018-05-17 09:54:41,951 INFO: App startup [in D:\flask\stageopdracht\app\__init__.py:33]
